Time slot   0
ld_routine
Time slot   1
	Loaded a process at input/proc/p1s, PID: 1 PRIO: 15
	CPU 3: Dispatched process  1
Time slot   2
Time slot   3
	CPU 3: Put process  1 to run queue
	CPU 3: Dispatched process  1
Time slot   4
	Loaded a process at input/proc/m0s, PID: 2 PRIO: 120
	CPU 3: Put process  1 to run queue
	CPU 3: Dispatched process  1
	CPU 1: Dispatched process  2
liballoc:178
Time slot   5
print_pgtbl:
 PDG=126862999196288 P4g=126862932052896 PUD=126862932053168 PMD=126862932053440
Time slot   6
liballoc:178
print_pgtbl:
 PDG=126862999196288 P4g=126862932052896 PUD=126862932053168 PMD=126862932053440
Time slot   7
	CPU 3: Put process  1 to run queue
	CPU 3: Dispatched process  1
	CPU 1: Put process  2 to run queue
	CPU 1: Dispatched process  2
libfree:218
print_pgtbl:
 PDG=126862999196288 P4g=126862932052896 PUD=126862932053168 PMD=126862932053440
	Loaded a process at input/proc/p0s, PID: 3 PRIO: 130
	CPU 2: Dispatched process  3
Time slot   8
liballoc:178
print_pgtbl:
 PDG=126862999203712 P4g=126862932055152 PUD=126862932055424 PMD=126862932055696
	Loaded a process at input/proc/s0, PID: 4 PRIO: 38
	CPU 3: Put process  1 to run queue
	CPU 3: Dispatched process  1
liballoc:178
Time slot   9
	CPU 0: Dispatched process  4
	CPU 1: Put process  2 to run queue
	CPU 1: Dispatched process  2
libwrite:502
print_pgtbl:
 PDG=126862999211168 P4g=126862797835168 PUD=126862797835440 PMD=126862797835712
print_pgtbl:
 PDG=126862999211168 P4g=126862797835168 PUD=126862797835440 PMD=126862797835712
Time slot  10
	CPU 2: Put process  3 to run queue
	CPU 2: Dispatched process  3
liballoc:178
print_pgtbl:
 PDG=126862999211168 P4g=126862797835168 PUD=126862797835440 PMD=126862797835712
libwrite:502
print_pgtbl:
 PDG=126862999211168 P4g=126862797835168 PUD=126862797835440 PMD=126862797835712
Time slot  11
	CPU 3: Processed  1 has finished
	CPU 1: Processed  2 has finished
	Loaded a process at input/proc/s3, PID: 5 PRIO: 39
	CPU 0: Put process  4 to run queue
	CPU 0: Dispatched process  4
Time slot  12
	CPU 3: Dispatched process  5
	CPU 2: Put process  3 to run queue
	CPU 2: Dispatched process  3
liballoc:178
print_pgtbl:
 PDG=126862999218464 P4g=126862797837376 PUD=126862797837648 PMD=126862797837920
Time slot  13
libwrite:502
print_pgtbl:
 PDG=126862999218464 P4g=126862797837376 PUD=126862797837648 PMD=126862797837920
	CPU 0: Put process  4 to run queue
	CPU 0: Dispatched process  4
	CPU 3: Put process  5 to run queue
	CPU 3: Dispatched process  5
	Loaded a process at input/proc/m1s, PID: 6 PRIO: 15
	CPU 2: Put process  3 to run queue
	CPU 2: Dispatched process  6
liballoc:178
print_pgtbl:
 PDG=126862999225568 P4g=126862797839024 PUD=126862797839296 PMD=126862797839568
Time slot  14
	CPU 1: Dispatched process  3
libread:426
print_pgtbl:
 PDG=126862999225568 P4g=126862797839024 PUD=126862797839296 PMD=126862797839568
Time slot  15
libwrite:502
print_pgtbl:
 PDG=126862999225568 P4g=126862797839024 PUD=126862797839296 PMD=126862797839568
	CPU 0: Put process  4 to run queue
	CPU 0: Dispatched process  4
liballoc:178
print_pgtbl:
 PDG=126862999225568 P4g=126862797839024 PUD=126862797839296 PMD=126862797839568
	Loaded a process at input/proc/s2, PID: 7 PRIO: 120
Time slot  16
	CPU 2: Put process  6 to run queue
	CPU 2: Dispatched process  6
	CPU 3: Put process  5 to run queue
	CPU 3: Dispatched process  5
	CPU 1: Put process  3 to run queue
	CPU 1: Dispatched process  7
Time slot  17
	CPU 0: Put process  4 to run queue
	CPU 0: Dispatched process  4
liballoc:178
print_pgtbl:
 PDG=126862999232912 P4g=126862797841232 PUD=126862797841504 PMD=126862797841776
	Loaded a process at input/proc/s1, PID: 8 PRIO: 0
Time slot  18
	CPU 3: Put process  5 to run queue
	CPU 3: Dispatched process  8
	CPU 2: Put process  6 to run queue
	CPU 2: Dispatched process  6
	CPU 1: Put process  7 to run queue
	CPU 1: Dispatched process  5
Time slot  19
	CPU 0: Put process  4 to run queue
	CPU 0: Dispatched process  4
Time slot  20
	CPU 1: Put process  5 to run queue
	CPU 1: Dispatched process  5
	CPU 2: Processed  6 has finished
	CPU 2: Dispatched process  7
	CPU 3: Put process  8 to run queue
	CPU 3: Dispatched process  8
Time slot  21
	CPU 0: Put process  4 to run queue
	CPU 0: Dispatched process  4
	CPU 1: Put process  5 to run queue
	CPU 1: Dispatched process  5
	CPU 2: Put process  7 to run queue
	CPU 2: Dispatched process  7
Time slot  22
	CPU 3: Put process  8 to run queue
	CPU 3: Dispatched process  8
	CPU 1: Processed  5 has finished
	CPU 1: Dispatched process  3
libread:426
print_pgtbl:
 PDG=126862999240048
Time slot  23
	CPU 0: Put process  4 to run queue
	CPU 0: Dispatched process  4
	CPU 3: Put process  8 to run queue
	CPU 3: Dispatched process  8
	CPU 2: Put process  7 to run queue
	CPU 2: Dispatched process  7
libwrite:502
print_pgtbl:
 PDG=126862999240048
	CPU 0: Processed  4 has finished
	CPU 0 stopped
Time slot  24
	CPU 3: Processed  8 has finished
	CPU 3 stopped
	CPU 1: Put process  3 to run queue
	CPU 1: Dispatched process  3
libread:426
print_pgtbl:
 PDG=126862999240048
Time slot  25
	CPU 2: Put process  7 to run queue
	CPU 2: Dispatched process  7
Time slot  26
	CPU 1: Put process  3 to run queue
	CPU 1: Dispatched process  3
Time slot  27
	CPU 2: Put process  7 to run queue
	CPU 2: Dispatched process  7
Time slot  28
	CPU 1: Processed  3 has finished
	CPU 1 stopped
Time slot  29
	CPU 2: Processed  7 has finished
	CPU 2 stopped
Time slot  30
