Time slot   0
ld_routine
Time slot   1
Time slot   2
Time slot   3
Time slot   4
Time slot   5
	Loaded a process at input/proc/m2s, PID: 1 PRIO: 120
	CPU 3: Dispatched process  1
Time slot   6
liballoc:170
print_pgtbl:
 PDG=7cc8e68cf010 P4g=7cc8e68ae010 PUD=7cc8e688d010 PMD=7cc8e686c010
liballoc:170
print_pgtbl:
 PDG=7cc8e68cf010 P4g=7cc8e68ae010 PUD=7cc8e688d010 PMD=7cc8e686c010
Time slot   7
	CPU 3: Put process  1 to run queue
	CPU 3: Dispatched process  1
libfree:194
print_pgtbl:
 PDG=7cc8e68cf010 P4g=7cc8e68ae010 PUD=7cc8e688d010 PMD=7cc8e686c010
Time slot   8
	Loaded a process at input/proc/s0, PID: 2 PRIO: 38
Time slot   9
	CPU 0: Dispatched process  2
	CPU 3: Put process  1 to run queue
Time slot  10
	CPU 3: Dispatched process  1
	Loaded a process at input/proc/s3, PID: 3 PRIO: 39
	CPU 0: Put process  2 to run queue
	CPU 0: Dispatched process  2
Time slot  11
	CPU 3: Put process  1 to run queue
	CPU 3: Dispatched process  3
	CPU 2: Dispatched process  1
Time slot  12
Time slot  13
	CPU 0: Put process  2 to run queue
	CPU 0: Dispatched process  2
	CPU 3: Put process  3 to run queue
	CPU 3: Dispatched process  3
	Loaded a process at input/proc/m2s, PID: 4 PRIO: 15
	CPU 2: Put process  1 to run queue
	CPU 2: Dispatched process  4
liballoc:170
print_pgtbl:
 PDG=7cc8e43b2010 P4g=7cc8e4391010 PUD=7cc8e4370010 PMD=7cc8e434f010
Time slot  14
liballoc:170
print_pgtbl:
 PDG=7cc8e43b2010 P4g=7cc8e4391010 PUD=7cc8e4370010 PMD=7cc8e434f010
Time slot  15
	CPU 0: Put process  2 to run queue
	CPU 0: Dispatched process  2
	CPU 1: Dispatched process  1
	Loaded a process at input/proc/s2, PID: 5 PRIO: 120
	CPU 2: Put process  4 to run queue
	CPU 2: Dispatched process  4
libfree:194
print_pgtbl:
 PDG=7cc8e43b2010 P4g=7cc8e4391010 PUD=7cc8e4370010 PMD=7cc8e434f010
Time slot  16
	CPU 3: Put process  3 to run queue
	CPU 3: Dispatched process  3
libfree:194
print_pgtbl:
 PDG=7cc8e68cf010 P4g=7cc8e68ae010 PUD=7cc8e688d010 PMD=7cc8e686c010
	Loaded a process at input/proc/s1, PID: 6 PRIO: 0
Time slot  17
	CPU 1: Put process  1 to run queue
	CPU 1: Dispatched process  6
	CPU 0: Put process  2 to run queue
	CPU 0: Dispatched process  2
	CPU 3: Put process  3 to run queue
Time slot  18
	CPU 3: Dispatched process  3
	CPU 2: Put process  4 to run queue
	CPU 2: Dispatched process  4
Time slot  19
	CPU 1: Put process  6 to run queue
	CPU 1: Dispatched process  6
	CPU 0: Put process  2 to run queue
	CPU 0: Dispatched process  2
	CPU 3: Put process  3 to run queue
Time slot  20
	CPU 3: Dispatched process  3
	CPU 2: Put process  4 to run queue
	CPU 2: Dispatched process  4
Time slot  21
	CPU 1: Put process  6 to run queue
	CPU 1: Dispatched process  6
	CPU 0: Put process  2 to run queue
	CPU 0: Dispatched process  2
	CPU 3: Put process  3 to run queue
	CPU 3: Dispatched process  3
Time slot  22
	CPU 2: Put process  4 to run queue
	CPU 2: Dispatched process  4
	CPU 3: Processed  3 has finished
	CPU 1: Put process  6 to run queue
	CPU 1: Dispatched process  6
Time slot  23
	CPU 0: Put process  2 to run queue
	CPU 0: Dispatched process  2
	CPU 3: Dispatched process  5
libfree:194
print_pgtbl:
 PDG=7cc8e43b2010 P4g=7cc8e4391010 PUD=7cc8e4370010 PMD=7cc8e434f010
Time slot  24
	CPU 2: Put process  4 to run queue
	CPU 1: Processed  6 has finished
	CPU 0: Processed  2 has finished
	CPU 0: Dispatched process  1
libfree:194
print_pgtbl:
 PDG=7cc8e68cf010 P4g=7cc8e68ae010 PUD=7cc8e688d010 PMD=7cc8e686c010
	CPU 1 stopped
	CPU 2: Dispatched process  4
libfree:194
print_pgtbl:
 PDG=7cc8e43b2010 P4g=7cc8e4391010 PUD=7cc8e4370010 PMD=7cc8e434f010
	CPU 3: Put process  5 to run queue
	CPU 3: Dispatched process  5
Time slot  25
Time slot  26
	CPU 0: Processed  1 has finished
	CPU 0 stopped
	CPU 2: Processed  4 has finished
	CPU 2 stopped
Time slot  27
	CPU 3: Put process  5 to run queue
	CPU 3: Dispatched process  5
Time slot  28
Time slot  29
	CPU 3: Put process  5 to run queue
	CPU 3: Dispatched process  5
Time slot  30
Time slot  31
	CPU 3: Put process  5 to run queue
	CPU 3: Dispatched process  5
Time slot  32
Time slot  33
	CPU 3: Put process  5 to run queue
	CPU 3: Dispatched process  5
Time slot  34
Time slot  35
	CPU 3: Processed  5 has finished
	CPU 3 stopped
