Time slot   0
ld_routine
Time slot   1
	Loaded a process at input/proc/p1s, PID: 1 PRIO: 15
	CPU 3: Dispatched process  1
Time slot   2
Time slot   3
	CPU 3: Put process  1 to run queue
	CPU 3: Dispatched process  1
Time slot   4
Time slot   5
	Loaded a process at input/proc/m0s, PID: 2 PRIO: 120
	CPU 3: Put process  1 to run queue
	CPU 3: Dispatched process  1
	CPU 2: Dispatched process  2
Time slot   6
liballoc:170
print_pgtbl:
 PDG=73495c797010 P4g=73495c776010 PUD=73495c755010 PMD=73495c734010
	Loaded a process at input/proc/p0s, PID: 3 PRIO: 130
liballoc:170
print_pgtbl:
 PDG=73495c797010 P4g=73495c776010 PUD=73495c755010 PMD=73495c734010
Time slot   7
	CPU 3: Put process  1 to run queue
	CPU 3: Dispatched process  1
Time slot   8
	CPU 1: Dispatched process  3
	CPU 2: Put process  2 to run queue
	CPU 2: Dispatched process  2
libfree:194
print_pgtbl:
 PDG=73495c797010 P4g=73495c776010 PUD=73495c755010 PMD=73495c734010
liballoc:170
print_pgtbl:
 PDG=73495c797010 P4g=73495c776010 PUD=73495c755010 PMD=73495c734010
Time slot   9
	Loaded a process at input/proc/s0, PID: 4 PRIO: 38
liballoc:170
print_pgtbl:
 PDG=73495c6f2010 P4g=73495c6d1010 PUD=73495c6b0010 PMD=73495c68f010
	CPU 3: Put process  1 to run queue
	CPU 1: Put process  3 to run queue
	CPU 1: Dispatched process  4
	CPU 3: Dispatched process  1
	CPU 0: Dispatched process  3
Time slot  10
	CPU 2: Put process  2 to run queue
	CPU 2: Dispatched process  2
libwrite:387
print_pgtbl:
 PDG=73495c797010 P4g=73495c776010 PUD=73495c755010 PMD=73495c734010
liballoc:170
print_pgtbl:
 PDG=73495c6f2010 P4g=73495c6d1010 PUD=73495c6b0010 PMD=73495c68f010
Time slot  11
libfree:194
print_pgtbl:
 PDG=73495c6f2010 P4g=73495c6d1010 PUD=73495c6b0010 PMD=73495c68f010
libwrite:387
print_pgtbl:
 PDG=73495c797010 P4g=73495c776010 PUD=73495c755010 PMD=73495c734010
	Loaded a process at input/proc/s3, PID: 5 PRIO: 39
	CPU 3: Processed  1 has finished
	CPU 2: Processed  2 has finished
	CPU 3: Dispatched process  5
Time slot  12
	CPU 1: Put process  4 to run queue
	CPU 1: Dispatched process  4
	CPU 0: Put process  3 to run queue
	CPU 0: Dispatched process  3
liballoc:170
print_pgtbl:
 PDG=73495c6f2010 P4g=73495c6d1010 PUD=73495c6b0010 PMD=73495c68f010
Time slot  13
libwrite:387
print_pgtbl:
 PDG=73495c6f2010 P4g=73495c6d1010 PUD=73495c6b0010 PMD=73495c68f010
	Loaded a process at input/proc/m1s, PID: 6 PRIO: 15
	CPU 1: Put process  4 to run queue
	CPU 3: Put process  5 to run queue
	CPU 3: Dispatched process  4
	CPU 0: Put process  3 to run queue
	CPU 0: Dispatched process  5
	CPU 1: Dispatched process  6
liballoc:170
print_pgtbl:
 PDG=73495c503010 P4g=73495c4e2010 PUD=73495c4c1010 PMD=73495c4a0010
Time slot  14
	CPU 2: Dispatched process  3
liballoc:170
print_pgtbl:
 PDG=73495c503010 P4g=73495c4e2010 PUD=73495c4c1010 PMD=73495c4a0010
Time slot  15
libread:333
	CPU 3: Put process  4 to run queue
Time slot  16
	CPU 0: Put process  5 to run queue
libwrite:387
	CPU 0: Dispatched process  5
	CPU 1: Put process  6 to run queue
print_pgtbl:
 PDG=73495c6f2010 P4g=73495c6d1010 PUD=73495c6b0010 PMD=73495c68f010
	CPU 1: Dispatched process  6
libfree:194
print_pgtbl:
 PDG=73495c503010 P4g=73495c4e2010 PUD=73495c4c1010 PMD=73495c4a0010
	Loaded a process at input/proc/s2, PID: 7 PRIO: 120
	CPU 3: Dispatched process  4
	Loaded a process at input/proc/s1, PID: 8 PRIO: 0
liballoc:170
print_pgtbl:
 PDG=73495c503010 P4g=73495c4e2010 PUD=73495c4c1010 PMD=73495c4a0010
Time slot  17
	CPU 2: Put process  3 to run queue
	CPU 2: Dispatched process  8
	CPU 3: Put process  4 to run queue
	CPU 3: Dispatched process  4
Time slot  18
	CPU 0: Put process  5 to run queue
	CPU 0: Dispatched process  5
	CPU 1: Put process  6 to run queue
	CPU 1: Dispatched process  6
libfree:194
print_pgtbl:
 PDG=73495c503010 P4g=73495c4e2010 PUD=73495c4c1010 PMD=73495c4a0010
	CPU 2: Put process  8 to run queue
	CPU 2: Dispatched process  8
libfree:194
print_pgtbl:
 PDG=73495c503010 P4g=73495c4e2010 PUD=73495c4c1010 PMD=73495c4a0010
Time slot  19
	CPU 3: Put process  4 to run queue
	CPU 3: Dispatched process  4
	CPU 1: Processed  6 has finished
	CPU 1: Dispatched process  7
	CPU 0: Put process  5 to run queue
	CPU 0: Dispatched process  5
Time slot  20
	CPU 2: Put process  8 to run queue
	CPU 2: Dispatched process  8
Time slot  21
	CPU 3: Put process  4 to run queue
	CPU 3: Dispatched process  4
Time slot  22
	CPU 1: Put process  7 to run queue
	CPU 1: Dispatched process  7
	CPU 0: Put process  5 to run queue
	CPU 0: Dispatched process  5
Time slot  23
	CPU 2: Put process  8 to run queue
	CPU 2: Dispatched process  8
	CPU 0: Processed  5 has finished
	CPU 0: Dispatched process  3
libread:333
	CPU 3: Put process  4 to run queue
libwrite:387
print_pgtbl:
 PDG=73495c6f2010 P4g=73495c6d1010 PUD=73495c6b0010 PMD=73495c68f010
	CPU 3: Dispatched process  4
	CPU 2: Processed  8 has finished
	CPU 2 stopped
Time slot  24
	CPU 1: Put process  7 to run queue
	CPU 1: Dispatched process  7
	CPU 3: Processed  4 has finished
Time slot  25
	CPU 3 stopped
	CPU 0: Put process  3 to run queue
	CPU 0: Dispatched process  3
libread:333
Time slot  26
	CPU 1: Put process  7 to run queue
	CPU 1: Dispatched process  7
Time slot  27
	CPU 0: Put process  3 to run queue
	CPU 0: Dispatched process  3
libfree:194
print_pgtbl:
 PDG=73495c6f2010 P4g=73495c6d1010 PUD=73495c6b0010 PMD=73495c68f010
Time slot  28
	CPU 1: Put process  7 to run queue
	CPU 1: Dispatched process  7
Time slot  29
	CPU 0: Processed  3 has finished
	CPU 0 stopped
Time slot  30
	CPU 1: Put process  7 to run queue
	CPU 1: Dispatched process  7
Time slot  31
Time slot  32
	CPU 1: Processed  7 has finished
	CPU 1 stopped
