Time slot   0
ld_routine
	Loaded a process at input/proc/p0s, PID: 1 PRIO: 130
Time slot   1
	CPU 1: Dispatched process  1
Time slot   2
liballoc:170
print_pgtbl:
 PDG=748fc6aba010 P4g=748fc6a99010 PUD=748fc6a78010 PMD=748fc6a57010
	Loaded a process at input/proc/m0s, PID: 2 PRIO: 120
	CPU 1: Put process  1 to run queue
	CPU 1: Dispatched process  2
liballoc:170
print_pgtbl:
 PDG=748fc6a15010 P4g=748fc47dc010 PUD=748fc47bb010 PMD=748fc479a010
Time slot   3
	CPU 3: Dispatched process  1
Time slot   4
liballoc:170
print_pgtbl:
 PDG=748fc6a15010 P4g=748fc47dc010 PUD=748fc47bb010 PMD=748fc479a010
liballoc:170
print_pgtbl:
 PDG=748fc6aba010 P4g=748fc6a99010 PUD=748fc6a78010 PMD=748fc6a57010
libfree:194
print_pgtbl:
 PDG=748fc6aba010 P4g=748fc6a99010 PUD=748fc6a78010 PMD=748fc6a57010
Time slot   5
	Loaded a process at input/proc/s1, PID: 3 PRIO: 0
	CPU 1: Put process  2 to run queue
	CPU 1: Dispatched process  3
	CPU 3: Put process  1 to run queue
	CPU 3: Dispatched process  1
	CPU 2: Dispatched process  2
Time slot   6
	Loaded a process at input/proc/p1s, PID: 4 PRIO: 15
liballoc:170
print_pgtbl:
 PDG=748fc6aba010 P4g=748fc6a99010 PUD=748fc6a78010 PMD=748fc6a57010
libfree:194
print_pgtbl:
 PDG=748fc6a15010 P4g=748fc47dc010 PUD=748fc47bb010 PMD=748fc479a010
libwrite:387
print_pgtbl:
 PDG=748fc6aba010 P4g=748fc6a99010 PUD=748fc6a78010 PMD=748fc6a57010
	CPU 1: Put process  3 to run queue
Time slot   7
	CPU 1: Dispatched process  3
liballoc:170
print_pgtbl:
 PDG=748fc6a15010 P4g=748fc47dc010 PUD=748fc47bb010 PMD=748fc479a010
	CPU 0: Dispatched process  4
	CPU 3: Put process  1 to run queue
	CPU 3: Dispatched process  1
libread:333
Time slot   8
	CPU 2: Put process  2 to run queue
	CPU 2: Dispatched process  2
libwrite:387
print_pgtbl:
 PDG=748fc6a15010 P4g=748fc47dc010 PUD=748fc47bb010 PMD=748fc479a010
libwrite:387
print_pgtbl:
 PDG=748fc6aba010 P4g=748fc6a99010 PUD=748fc6a78010 PMD=748fc6a57010
Time slot   9
libwrite:387
	Loaded a process at input/proc/s3, PID: 5 PRIO: 39
	CPU 0: Put process  4 to run queue
	CPU 0: Dispatched process  4
	CPU 1: Put process  3 to run queue
	CPU 1: Dispatched process  3
print_pgtbl:
 PDG=748fc6a15010 P4g=748fc47dc010 PUD=748fc47bb010 PMD=748fc479a010
	CPU 3: Put process  1 to run queue
	CPU 3: Dispatched process  5
Time slot  10
	Loaded a process at input/proc/s2, PID: 6 PRIO: 120
	CPU 2: Processed  2 has finished
	CPU 2: Dispatched process  6
Time slot  11
	CPU 0: Put process  4 to run queue
	CPU 0: Dispatched process  4
	CPU 1: Put process  3 to run queue
	CPU 1: Dispatched process  3
	Loaded a process at input/proc/m1s, PID: 7 PRIO: 15
	CPU 3: Put process  5 to run queue
	CPU 3: Dispatched process  7
liballoc:170
print_pgtbl:
 PDG=748fc44c4010 P4g=748fc44a3010 PUD=748fc4482010 PMD=748fc4461010
	Loaded a process at input/proc/s0, PID: 8 PRIO: 38
	CPU 1: Processed  3 has finished
	CPU 1: Dispatched process  5
Time slot  12
	CPU 2: Put process  6 to run queue
	CPU 2: Dispatched process  8
liballoc:170
print_pgtbl:
 PDG=748fc44c4010 P4g=748fc44a3010 PUD=748fc4482010 PMD=748fc4461010
Time slot  13
	CPU 0: Put process  4 to run queue
	CPU 0: Dispatched process  4
	CPU 2: Put process  8 to run queue
	CPU 2: Dispatched process  8
	CPU 3: Put process  7 to run queue
	CPU 3: Dispatched process  7
libfree:194
print_pgtbl:
 PDG=748fc44c4010 P4g=748fc44a3010 PUD=748fc4482010 PMD=748fc4461010
Time slot  14
	CPU 1: Put process  5 to run queue
	CPU 1: Dispatched process  5
liballoc:170
	CPU 0: Put process  4 to run queue
	CPU 0: Dispatched process  4
print_pgtbl:
 PDG=748fc44c4010 P4g=748fc44a3010 PUD=748fc4482010 PMD=748fc4461010
Time slot  15
	CPU 2: Put process  8 to run queue
	CPU 2: Dispatched process  8
	CPU 3: Put process  7 to run queue
	CPU 1: Put process  5 to run queue
	CPU 1: Dispatched process  5
	CPU 3: Dispatched process  7
libfree:194
print_pgtbl:
 PDG=748fc44c4010 P4g=748fc44a3010 PUD=748fc4482010 PMD=748fc4461010
Time slot  16
libfree:194
	CPU 0: Processed  4 has finished
	CPU 0: Dispatched process  6
print_pgtbl:
 PDG=748fc44c4010 P4g=748fc44a3010 PUD=748fc4482010 PMD=748fc4461010
Time slot  17
	CPU 3: Processed  7 has finished
	CPU 3: Dispatched process  1
	CPU 2: Put process  8 to run queue
Time slot  18
	CPU 1: Put process  5 to run queue
	CPU 1: Dispatched process  5
	CPU 2: Dispatched process  8
libread:333
libwrite:387
print_pgtbl:
 PDG=748fc6aba010 P4g=748fc6a99010 PUD=748fc6a78010 PMD=748fc6a57010
Time slot  19
	CPU 0: Put process  6 to run queue
	CPU 0: Dispatched process  6
	CPU 3: Put process  1 to run queue
	CPU 3: Dispatched process  1
libread:333
	CPU 2: Put process  8 to run queue
	CPU 2: Dispatched process  8
Time slot  20
	CPU 1: Put process  5 to run queue
	CPU 1: Dispatched process  5
Time slot  21
	CPU 0: Put process  6 to run queue
	CPU 0: Dispatched process  6
	CPU 1: Processed  5 has finished
	CPU 1 stopped
	CPU 3: Put process  1 to run queue
	CPU 3: Dispatched process  1
libfree:194
print_pgtbl:
 PDG=748fc6aba010 P4g=748fc6a99010 PUD=748fc6a78010 PMD=748fc6a57010
Time slot  22
	CPU 2: Put process  8 to run queue
	CPU 2: Dispatched process  8
Time slot  23
	CPU 0: Put process  6 to run queue
	CPU 0: Dispatched process  6
	CPU 3: Processed  1 has finished
Time slot  24
	CPU 3 stopped
	CPU 2: Put process  8 to run queue
	CPU 2: Dispatched process  8
Time slot  25
	CPU 0: Put process  6 to run queue
	CPU 0: Dispatched process  6
	CPU 2: Put process  8 to run queue
	CPU 2: Dispatched process  8
Time slot  26
Time slot  27
	CPU 2: Processed  8 has finished
	CPU 2 stopped
	CPU 0: Processed  6 has finished
	CPU 0 stopped
