Time slot   0
ld_routine
	Loaded a process at input/proc/p0s, PID: 1 PRIO: 130
Time slot   1
	CPU 3: Dispatched process  1
Time slot   2
	Loaded a process at input/proc/m0s, PID: 2 PRIO: 120
	CPU 2: Dispatched process  2
liballoc:170
print_pgtbl:
 PDG=76559b242010 P4g=76559b221010 PUD=7655987db010 PMD=7655987ba010
liballoc:170
print_pgtbl:
 PDG=765598778010 P4g=765598757010 PUD=765598736010 PMD=765598715010
Time slot   3
	CPU 3: Put process  1 to run queue
	CPU 3: Dispatched process  1
liballoc:170
	Loaded a process at input/proc/s3, PID: 3 PRIO: 39
Time slot   4
print_pgtbl:
 PDG=76559b242010 P4g=76559b221010 PUD=7655987db010 PMD=7655987ba010
liballoc:170
print_pgtbl:
 PDG=765598778010 P4g=765598757010 PUD=765598736010 PMD=765598715010
libfree:194
print_pgtbl:
	CPU 2: Put process  2 to run queue
	CPU 1: Dispatched process  3
	Loaded a process at input/proc/s0, PID: 4 PRIO: 38
	CPU 2: Dispatched process  4
 PDG=76559b242010 P4g=76559b221010 PUD=7655987db010 PMD=7655987ba010
Time slot   5
	CPU 3: Put process  1 to run queue
	CPU 3: Dispatched process  2
libfree:194
print_pgtbl:
 PDG=765598778010 P4g=765598757010 PUD=765598736010 PMD=765598715010
Time slot   6
	CPU 0: Dispatched process  1
liballoc:170
print_pgtbl:
 PDG=76559b242010 P4g=76559b221010 PUD=7655987db010 PMD=7655987ba010
liballoc:170
libwrite:387
print_pgtbl:
 PDG=76559b242010 P4g=76559b221010 PUD=7655987db010 PMD=7655987ba010
print_pgtbl:
 PDG=765598778010 P4g=765598757010 PUD=765598736010 PMD=765598715010
	CPU 2: Put process  4 to run queue
	CPU 2: Dispatched process  4
Time slot   7
	CPU 1: Put process  3 to run queue
	CPU 1: Dispatched process  3
	CPU 3: Put process  2 to run queue
	CPU 3: Dispatched process  2
libwrite:387
print_pgtbl:
 PDG=765598778010 P4g=765598757010 PUD=765598736010 PMD=765598715010
	CPU 0: Put process  1 to run queue
	CPU 0: Dispatched process  1
libread:333
Time slot   8
libwrite:387
print_pgtbl:
 PDG=765598778010 P4g=765598757010 PUD=765598736010 PMD=765598715010
	CPU 2: Put process  4 to run queue
	CPU 2: Dispatched process  4
Time slot   9
libwrite:387
print_pgtbl:
 PDG=76559b242010 P4g=76559b221010 PUD=7655987db010 PMD=7655987ba010
	CPU 1: Put process  3 to run queue
	CPU 1: Dispatched process  3
	Loaded a process at input/proc/m1s, PID: 5 PRIO: 15
	CPU 3: Processed  2 has finished
	CPU 3: Dispatched process  5
Time slot  10
	CPU 0: Put process  1 to run queue
	CPU 0: Dispatched process  1
libread:333
liballoc:170
print_pgtbl:
 PDG=765598589010 P4g=765598568010 PUD=765598547010 PMD=765598526010
	Loaded a process at input/proc/p1s, PID: 6 PRIO: 15
	CPU 2: Put process  4 to run queue
	CPU 2: Dispatched process  4
liballoc:170
print_pgtbl:
Time slot  11
libwrite:387
	CPU 1: Put process  3 to run queue
 PDG=765598589010 P4g=765598568010 PUD=765598547010 PMD=765598526010
print_pgtbl:
 PDG=76559b242010 P4g=76559b221010 PUD=7655987db010 PMD=7655987ba010
	CPU 1: Dispatched process  6
	CPU 3: Put process  5 to run queue
	CPU 3: Dispatched process  5
libfree:194
print_pgtbl:
 PDG=765598589010 P4g=765598568010 PUD=765598547010 PMD=765598526010
Time slot  12
	CPU 0: Put process  1 to run queue
	CPU 0: Dispatched process  3
liballoc:170
Time slot  13
	Loaded a process at input/proc/s2, PID: 7 PRIO: 120
	CPU 2: Put process  4 to run queue
	CPU 1: Put process  6 to run queue
	CPU 2: Dispatched process  4
print_pgtbl:
 PDG=765598589010 P4g=765598568010 PUD=765598547010 PMD=765598526010
	CPU 1: Dispatched process  6
	CPU 3: Put process  5 to run queue
	CPU 3: Dispatched process  5
libfree:194
print_pgtbl:
 PDG=765598589010 P4g=765598568010 PUD=765598547010 PMD=765598526010
Time slot  14
	CPU 0: Put process  3 to run queue
	CPU 0: Dispatched process  3
libfree:194
print_pgtbl:
 PDG=765598589010 P4g=765598568010 PUD=765598547010 PMD=765598526010
	CPU 2: Put process  4 to run queue
	CPU 2: Dispatched process  4
	CPU 1: Put process  6 to run queue
	CPU 1: Dispatched process  6
Time slot  15
	Loaded a process at input/proc/s1, PID: 8 PRIO: 0
	CPU 3: Processed  5 has finished
	CPU 3: Dispatched process  8
Time slot  16
	CPU 0: Put process  3 to run queue
	CPU 0: Dispatched process  3
	CPU 2: Put process  4 to run queue
	CPU 2: Dispatched process  4
	CPU 1: Put process  6 to run queue
	CPU 1: Dispatched process  6
	CPU 0: Processed  3 has finished
Time slot  17
	CPU 0: Dispatched process  7
	CPU 3: Put process  8 to run queue
	CPU 3: Dispatched process  8
Time slot  18
	CPU 2: Put process  4 to run queue
	CPU 2: Dispatched process  4
	CPU 0: Put process  7 to run queue
	CPU 0: Dispatched process  7
	CPU 1: Put process  6 to run queue
	CPU 1: Dispatched process  6
Time slot  19
	CPU 3: Put process  8 to run queue
	CPU 3: Dispatched process  8
Time slot  20
	CPU 2: Processed  4 has finished
	CPU 2: Dispatched process  1
libread:333
Time slot  21
	CPU 0: Put process  7 to run queue
	CPU 0: Dispatched process  7
	CPU 1: Processed  6 has finished
	CPU 1 stopped
	CPU 3: Put process  8 to run queue
	CPU 3: Dispatched process  8
Time slot  22
	CPU 2: Put process  1 to run queue
	CPU 2: Dispatched process  1
libfree:194
print_pgtbl:
 PDG=76559b242010 P4g=76559b221010 PUD=7655987db010 PMD=7655987ba010
	CPU 3: Processed  8 has finished
	CPU 3 stopped
Time slot  23
	CPU 0: Put process  7 to run queue
	CPU 0: Dispatched process  7
	CPU 2: Processed  1 has finished
	CPU 2 stopped
Time slot  24
Time slot  25
	CPU 0: Put process  7 to run queue
	CPU 0: Dispatched process  7
Time slot  26
Time slot  27
	CPU 0: Put process  7 to run queue
	CPU 0: Dispatched process  7
Time slot  28
Time slot  29
	CPU 0: Processed  7 has finished
	CPU 0 stopped
