Time slot   0
ld_routine
Time slot   1
	Loaded a process at input/proc/p0s, PID: 1 PRIO: 130
	CPU 2: Dispatched process  1
	Loaded a process at input/proc/m0s, PID: 2 PRIO: 120
Time slot   2
	CPU 0: Dispatched process  2
liballoc:170
print_pgtbl:
 PDG=769ccb92d010 P4g=769ccb90c010 PUD=769ccb8eb010 PMD=769ccb8ca010
liballoc:170
print_pgtbl:
 PDG=769ccb888010 P4g=769ccb867010 PUD=769ccb846010 PMD=769ccb825010
	CPU 2: Put process  1 to run queue
liballoc:170
print_pgtbl:
 PDG=769ccb888010 P4g=769ccb867010 PUD=769ccb846010 PMD=769ccb825010
	CPU 2: Dispatched process  1
liballoc:170
print_pgtbl:
 PDG=769ccb92d010 P4g=769ccb90c010 PUD=769ccb8eb010 PMD=769ccb8ca010
Time slot   3
	Loaded a process at input/proc/s3, PID: 3 PRIO: 39
Time slot   4
libfree:194
print_pgtbl:
 PDG=769ccb92d010 P4g=769ccb90c010 PUD=769ccb8eb010 PMD=769ccb8ca010
	CPU 0: Put process  2 to run queue
	CPU 0: Dispatched process  3
	CPU 2: Put process  1 to run queue
	CPU 2: Dispatched process  1
liballoc:170
print_pgtbl:
 PDG=769ccb92d010 P4g=769ccb90c010 PUD=769ccb8eb010 PMD=769ccb8ca010
Time slot   5
	Loaded a process at input/proc/s0, PID: 4 PRIO: 38
	CPU 3: Dispatched process  2
libfree:194
print_pgtbl:
 PDG=769ccb888010 P4g=769ccb867010 PUD=769ccb846010 PMD=769ccb825010
liballoc:170
Time slot   6
print_pgtbl:
 PDG=769ccb888010 P4g=769ccb867010 PUD=769ccb846010 PMD=769ccb825010
libwrite:387
	CPU 0: Put process  3 to run queue
	CPU 0: Dispatched process  3
print_pgtbl:
 PDG=769ccb92d010 P4g=769ccb90c010 PUD=769ccb8eb010 PMD=769ccb8ca010
	CPU 1: Dispatched process  4
	CPU 3: Put process  2 to run queue
Time slot   7
	CPU 3: Dispatched process  2
libwrite:387
print_pgtbl:
 PDG=769ccb888010 P4g=769ccb867010 PUD=769ccb846010 PMD=769ccb825010
	CPU 2: Put process  1 to run queue
	CPU 2: Dispatched process  1
libread:333
	CPU 1: Put process  4 to run queue
libwrite:387
	CPU 1: Dispatched process  4
Time slot   8
print_pgtbl:
libwrite:387
print_pgtbl:
 PDG=769ccb92d010 P4g=769ccb90c010 PUD=769ccb8eb010 PMD=769ccb8ca010
 PDG=769ccb888010 P4g=769ccb867010 PUD=769ccb846010 PMD=769ccb825010
	CPU 0: Put process  3 to run queue
	CPU 0: Dispatched process  3
	CPU 3: Processed  2 has finished
	Loaded a process at input/proc/m1s, PID: 5 PRIO: 15
Time slot   9
	CPU 2: Put process  1 to run queue
	CPU 2: Dispatched process  5
liballoc:170
print_pgtbl:
 PDG=769cc846f010 P4g=769cc844e010 PUD=769cc842d010 PMD=769cc840c010
	CPU 3: Dispatched process  1
Time slot  10
liballoc:170
	CPU 1: Put process  4 to run queue
print_pgtbl:
 PDG=769cc846f010 P4g=769cc844e010 PUD=769cc842d010 PMD=769cc840c010
	CPU 1: Dispatched process  4
libread:333
	CPU 0: Put process  3 to run queue
	CPU 0: Dispatched process  3
	Loaded a process at input/proc/p1s, PID: 6 PRIO: 15
	CPU 2: Put process  5 to run queue
libwrite:387
print_pgtbl:
 PDG=769ccb92d010 P4g=769ccb90c010 PUD=769ccb8eb010 PMD=769ccb8ca010
	CPU 2: Dispatched process  6
Time slot  11
	CPU 3: Put process  1 to run queue
	CPU 3: Dispatched process  5
libfree:194
print_pgtbl:
 PDG=769cc846f010 P4g=769cc844e010 PUD=769cc842d010 PMD=769cc840c010
Time slot  12
	CPU 0: Put process  3 to run queue
	CPU 0: Dispatched process  3
	CPU 1: Put process  4 to run queue
	CPU 1: Dispatched process  4
liballoc:170
print_pgtbl:
 PDG=769cc846f010 P4g=769cc844e010 PUD=769cc842d010 PMD=769cc840c010
Time slot  13
	Loaded a process at input/proc/s2, PID: 7 PRIO: 120
	CPU 2: Put process  6 to run queue
	CPU 2: Dispatched process  6
	CPU 3: Put process  5 to run queue
	CPU 3: Dispatched process  5
libfree:194
print_pgtbl:
 PDG=769cc846f010 P4g=769cc844e010 PUD=769cc842d010 PMD=769cc840c010
Time slot  14
	CPU 0: Put process  3 to run queue
	CPU 0: Dispatched process  3
	CPU 1: Put process  4 to run queue
	CPU 1: Dispatched process  4
libfree:194
Time slot  15
	CPU 0: Processed  3 has finished
	CPU 0: Dispatched process  7
print_pgtbl:
 PDG=769cc846f010 P4g=769cc844e010 PUD=769cc842d010 PMD=769cc840c010
	CPU 2: Put process  6 to run queue
	CPU 2: Dispatched process  6
	CPU 3: Processed  5 has finished
	CPU 3: Dispatched process  1
libread:333
Time slot  16
	CPU 1: Put process  4 to run queue
	CPU 1: Dispatched process  4
	Loaded a process at input/proc/s1, PID: 8 PRIO: 0
	CPU 2: Put process  6 to run queue
	CPU 0: Put process  7 to run queue
	CPU 0: Dispatched process  8
	CPU 2: Dispatched process  6
Time slot  17
	CPU 3: Put process  1 to run queue
	CPU 3: Dispatched process  7
Time slot  18
	CPU 1: Put process  4 to run queue
	CPU 1: Dispatched process  4
	CPU 2: Put process  6 to run queue
	CPU 2: Dispatched process  6
Time slot  19
	CPU 0: Put process  8 to run queue
	CPU 0: Dispatched process  8
	CPU 3: Put process  7 to run queue
	CPU 3: Dispatched process  7
	CPU 1: Put process  4 to run queue
	CPU 1: Dispatched process  4
Time slot  20
	CPU 2: Processed  6 has finished
	CPU 2: Dispatched process  1
libfree:194
print_pgtbl:
Time slot  21
	CPU 1: Processed  4 has finished
	CPU 1 stopped
	CPU 0: Put process  8 to run queue
 PDG=769ccb92d010 P4g=769ccb90c010 PUD=769ccb8eb010 PMD=769ccb8ca010
	CPU 0: Dispatched process  8
	CPU 3: Put process  7 to run queue
	CPU 3: Dispatched process  7
Time slot  22
	CPU 2: Processed  1 has finished
	CPU 2 stopped
Time slot  23
	CPU 0: Put process  8 to run queue
	CPU 0: Dispatched process  8
Time slot  24
	CPU 3: Put process  7 to run queue
	CPU 3: Dispatched process  7
	CPU 0: Processed  8 has finished
	CPU 0 stopped
Time slot  25
Time slot  26
	CPU 3: Put process  7 to run queue
	CPU 3: Dispatched process  7
Time slot  27
Time slot  28
	CPU 3: Processed  7 has finished
	CPU 3 stopped
