Time slot   0
	Loaded a process at input/proc/s0, PID: 1 PRIO: 1
	CPU 1: Dispatched process  1
Time slot   1
	CPU 1: Put process  1 to run queue (1/10)
	CPU 1: Dispatched process  1
Time slot   2
	Loaded a process at input/proc/s1, PID: 2 PRIO: 0
	CPU 1: Put process  1 to run queue (2/10)
	CPU 1: Dispatched process  2
	CPU 0: Dispatched process  1
Time slot   3
	CPU 1: Put process  2 to run queue (1/5)
	CPU 1: Dispatched process  2
	CPU 0: Put process  1 to run queue (3/10)
	CPU 0: Dispatched process  1
Time slot   4
	CPU 1: Put process  2 to run queue (2/5)
	CPU 1: Dispatched process  2
	CPU 0: Put process  1 to run queue (4/10)
	CPU 0: Dispatched process  1
Time slot   5
	Loaded a process at input/proc/s1, PID: 3 PRIO: 2
	CPU 1: Put process  2 to run queue (3/5)
	CPU 1: Dispatched process  2
	CPU 0: Put process  1 to run queue (5/10)
	CPU 0: Dispatched process  1
Time slot   6
	CPU 1: Put process  2 to run queue (4/5)
	CPU 1: Dispatched process  2
	CPU 0: Put process  1 to run queue (6/10)
	CPU 0: Dispatched process  3
	Loaded a process at input/proc/s0, PID: 4 PRIO: 0
Time slot   7
	CPU 1: Processed  2 has finished (5/5)
	CPU 0: Put process  3 to run queue (1/5)
	CPU 0: Dispatched process  4
	CPU 1: Dispatched process  1
Time slot   8
	CPU 1: Put process  1 to run queue (7/10)
	CPU 0: Put process  4 to run queue (1/10)
	CPU 0: Dispatched process  4
	CPU 1: Dispatched process  1
Time slot   9
	CPU 1: Put process  1 to run queue (8/10)
	CPU 1: Dispatched process  3
	CPU 0: Put process  4 to run queue (2/10)
	CPU 0: Dispatched process  4
Time slot  10
	CPU 1: Put process  3 to run queue (2/5)
	CPU 1: Dispatched process  1
	CPU 0: Put process  4 to run queue (3/10)
	CPU 0: Dispatched process  4
Time slot  11
	CPU 1: Put process  1 to run queue (9/10)
	CPU 1: Dispatched process  1
	CPU 0: Put process  4 to run queue (4/10)
	CPU 0: Dispatched process  4
Time slot  12
	CPU 1: Processed  1 has finished (10/10)
	CPU 1: Dispatched process  3
	CPU 0: Put process  4 to run queue (5/10)
	CPU 0: Dispatched process  4
Time slot  13
	CPU 1: Put process  3 to run queue (3/5)
	CPU 1: Dispatched process  3
	CPU 0: Put process  4 to run queue (6/10)
	CPU 0: Dispatched process  4
Time slot  14
	CPU 1: Put process  3 to run queue (4/5)
	CPU 1: Dispatched process  3
	CPU 0: Put process  4 to run queue (7/10)
	CPU 0: Dispatched process  4
Time slot  15
	CPU 1: Processed  3 has finished (5/5)
	CPU 1 stopped
	CPU 0: Put process  4 to run queue (8/10)
	CPU 0: Dispatched process  4
Time slot  16
	CPU 0: Put process  4 to run queue (9/10)
	CPU 0: Dispatched process  4
Time slot  17
	CPU 0: Processed  4 has finished (10/10)
	CPU 0 stopped
